<?xml version="1.0"?>
<robot xmlns:xacro="http://www.ros.org/wiki/xacro" name="HoverMower">

  <xacro:property name="base_width" value="0.28"/>
  <xacro:property name="base_len" value="0.536"/>
  <xacro:property name="base_height" value="0.26"/>
  <xacro:property name="wheel_radius" value="0.085"/>
  <xacro:property name="base_wheel_gap" value="0.01"/>
  <xacro:property name="wheel_separation" value="0.36"/>
  <xacro:property name="wheel_joint_offset" value="0"/>
  <xacro:property name="caster_wheel_radius" value="0.035"/>
  <xacro:property name="caster_wheel_joint_offset" value="0.12"/>

 <!-- <xacro:include filename="$(find rosmower)/urdf/rosmower_gazebo_plugins.xacro"/>
  -->
  <material name="blue">
    <color rgba="0 0 0.8 1"/>
  </material>
  <material name="black">
    <color rgba="0 0 0 1"/>
  </material>
  <material name="darkgray">
    <color rgba="0.2 0.2 0.2 1"/>
  </material>
  <material name="lightgray">
    <color rgba="0.8 0.8 0.8 1"/>
  </material>
  <material name="white">
    <color rgba="1 1 1 1"/>
  </material>
  <material name="red">
    <color rgba="0.8 0.0 0.0 1.0"/>
  </material>


  <xacro:macro name="box_inertia" params="m w h d">
    <inertial>
      <mass value="${m}"/>
      <inertia ixx="${m / 12.0 * (d*d + h*h)}" ixy="0.0" ixz="0.0" iyy="${m / 12.0 * (w*w + h*h)}" iyz="0.0" izz="${m / 12.0 * (w*w + d*d)}"/>
    </inertial>
  </xacro:macro>

  <link name="base_footprint">
    <xacro:box_inertia m="8" w="0.001" h="0.001" d="0.001"/>
    <visual>
      <origin xyz="0 0 0" rpy="0 0 0" />
      <material name="white"/>
        <geometry>
            <box size="0.001 0.001 0.001" />
        </geometry>
    </visual>
  </link> 

 
  <link name="base_link">
    <xacro:box_inertia m="1" w="${base_len}" h="${base_width}" d="0.01"/>
    <visual>
      <material name="lightgray"/>
      <geometry>
        <mesh filename="package://rosmower/meshes/robot_body.dae" />
      </geometry>
    </visual>
    <collision>
      <geometry>
        <mesh filename="package://rosmower/meshes/robot_body.dae"/>
      </geometry>
    </collision>
  </link>

 
  <joint name="base_link_joint" type="fixed">
    <origin xyz="0 0 0.08" rpy="0 0 0" />
    <parent link="base_footprint"/>
    <child link="base_link" />
  </joint>

  <xacro:macro name="wheel" params="prefix reflect rotate">
    <link name="${prefix}_wheel">
      <visual>
        <material name="darkgray"/>
        <geometry>
	        <mesh filename="package://rosmower/meshes/wheel.dae" />
        </geometry>
    </visual>
    <collision>
      <geometry>
        <mesh filename="package://rosmower/meshes/wheel.dae" />
      </geometry>
    </collision> 
    </link>

    <joint name="${prefix}_wheel" type="continuous">
      <axis xyz="0 1 0" rpy="0 0 0" />
      <parent link="base_link"/>
      <child link="${prefix}_wheel"/>
      <origin xyz="${wheel_joint_offset} ${((base_width/2)+base_wheel_gap)*reflect} 0" rpy="0 0 ${0+rotate}"/>
    </joint>
  </xacro:macro>

  <xacro:wheel prefix="left" reflect="1" rotate="0"/>
  <xacro:wheel prefix="right" reflect="-1" rotate="3.14159"/>

  <joint name="imu_joint" type="fixed">
    <parent link="base_link" />
    <child link="imu" />
    <origin xyz="0.092 0.0 0.105" rpy="0 0 0" />
  </joint>
  <link name="imu" />

  <joint name="lidar_joint" type="fixed">
    <parent link="base_link" />
    <child link="lidar_frame" />
    <origin xyz="0.242 0.0 0.195" rpy="0 0 0" />
  </joint>
  <link name="lidar_frame" type="fixed"/>

  <joint name="gps_joint" type="fixed">
    <parent link="base_link" />
    <child link="gps_frame" />
    <origin xyz="0.310 0.0 0.195" rpy="0 0 0" />
  </joint>
  <link name="gps_frame" type="fixed"/>

  <joint name="camera_joint" type="fixed">
    <origin xyz="0.35 0 0.117" rpy="0 0 0" />
    <parent link="base_link" />
    <child link="camera_link" />
  </joint>
  <link name="camera_link" type="fixed"/>
  
  <joint name="perimeter_left_joint" type="fixed">
    <origin xyz="0.385 0.081 0.025" rpy="0 0 0" />
    <parent link="base_link" />
    <child link="perimeter_left" />
  </joint>
  <link name="perimeter_left" type="fixed"/>
  
  <joint name="perimeter_right_joint" type="fixed">
    <origin xyz="0.385 -0.081 0.025" rpy="0 0 0" />
    <parent link="base_link" />
    <child link="perimeter_right" />
  </joint>
  <link name="perimeter_right" type="fixed"/>  

  <joint name="bumper_left_joint" type="fixed">
    <origin xyz="0.45 0.101 0.040" rpy="0 0 0" />
    <parent link="base_link" />
    <child link="bumper_left" />
  </joint>
  <link name="bumper_left" type="fixed"/>

  <joint name="bumper_right_joint" type="fixed">
    <origin xyz="0.45 -0.101 0.040" rpy="0 0 0" />
    <parent link="base_link" />
    <child link="bumper_right" />
  </joint>
  <link name="bumper_right" type="fixed"/>

</robot>
